{
 "cells": [
  {
   "cell_type": "code",
   "execution_count": 14,
   "id": "f4065c77",
   "metadata": {},
   "outputs": [],
   "source": [
    "import tensorflow as tf\n",
    "#from tensorflow import keras"
   ]
  },
  {
   "cell_type": "code",
   "execution_count": 15,
   "id": "1783094c",
   "metadata": {},
   "outputs": [],
   "source": [
    "from tensorflow.keras.preprocessing.image import load_img\n",
    "from tensorflow.keras.preprocessing.image import ImageDataGenerator\n",
    "from tensorflow.keras import layers, models"
   ]
  },
  {
   "cell_type": "code",
   "execution_count": null,
   "id": "80718391",
   "metadata": {},
   "outputs": [],
   "source": [
    "!wget https://github.com/alexeygrigorev/dino-or-dragon/releases/download/data/dino-dragon.zip\n",
    "!unzip dino-dragon.zip"
   ]
  },
  {
   "cell_type": "code",
   "execution_count": 50,
   "id": "3c5c50d9",
   "metadata": {},
   "outputs": [],
   "source": [
    "model = models.Sequential()\n",
    "model.add(layers.Conv2D(filters = 32, kernel_size = (3, 3), activation='relu', input_shape=(150, 150, 3)))\n",
    "model.add(layers.MaxPooling2D((2, 2)))\n",
    "model.add(layers.Flatten())\n",
    "model.add(layers.Dense(64, activation='relu'))\n",
    "model.add(layers.Dense(1, activation='sigmoid'))\n",
    "\n",
    "opt = tf.keras.optimizers.SGD(learning_rate=0.002, momentum=0.8)\n",
    "\n",
    "model.compile(optimizer = opt, \n",
    "              loss=tf.keras.losses.BinaryCrossentropy(),\n",
    "              metrics=['accuracy'])"
   ]
  },
  {
   "cell_type": "code",
   "execution_count": 51,
   "id": "ff242bce",
   "metadata": {},
   "outputs": [
    {
     "name": "stdout",
     "output_type": "stream",
     "text": [
      "Model: \"sequential_8\"\n",
      "_________________________________________________________________\n",
      " Layer (type)                Output Shape              Param #   \n",
      "=================================================================\n",
      " conv2d_8 (Conv2D)           (None, 148, 148, 32)      896       \n",
      "                                                                 \n",
      " max_pooling2d_8 (MaxPooling  (None, 74, 74, 32)       0         \n",
      " 2D)                                                             \n",
      "                                                                 \n",
      " flatten_8 (Flatten)         (None, 175232)            0         \n",
      "                                                                 \n",
      " dense_15 (Dense)            (None, 64)                11214912  \n",
      "                                                                 \n",
      " dense_16 (Dense)            (None, 1)                 65        \n",
      "                                                                 \n",
      "=================================================================\n",
      "Total params: 11,215,873\n",
      "Trainable params: 11,215,873\n",
      "Non-trainable params: 0\n",
      "_________________________________________________________________\n"
     ]
    }
   ],
   "source": [
    "model.summary()"
   ]
  },
  {
   "cell_type": "code",
   "execution_count": 62,
   "id": "31bdbcd6",
   "metadata": {},
   "outputs": [
    {
     "name": "stdout",
     "output_type": "stream",
     "text": [
      "Found 1594 images belonging to 2 classes.\n"
     ]
    }
   ],
   "source": [
    "train_gen = ImageDataGenerator(rescale=1./255)\n",
    "\n",
    "train_ds = train_gen.flow_from_directory(\n",
    "    r\"./train/\",\n",
    "    target_size=(150, 150),\n",
    "    batch_size=20,\n",
    "    shuffle = True,\n",
    "    class_mode = 'binary'\n",
    ")"
   ]
  },
  {
   "cell_type": "code",
   "execution_count": 63,
   "id": "5a8901a9",
   "metadata": {},
   "outputs": [
    {
     "name": "stdout",
     "output_type": "stream",
     "text": [
      "Found 394 images belonging to 2 classes.\n"
     ]
    }
   ],
   "source": [
    "test_gen = ImageDataGenerator(rescale=1./255)\n",
    "\n",
    "test_ds = test_gen.flow_from_directory(\n",
    "    r\"./test/\",\n",
    "    target_size=(150, 150),\n",
    "    batch_size=20,\n",
    "    shuffle = True,\n",
    "    class_mode = 'binary'\n",
    ")"
   ]
  },
  {
   "cell_type": "code",
   "execution_count": 64,
   "id": "01cbc333",
   "metadata": {},
   "outputs": [
    {
     "name": "stdout",
     "output_type": "stream",
     "text": [
      "Epoch 1/10\n"
     ]
    },
    {
     "name": "stderr",
     "output_type": "stream",
     "text": [
      "2022-11-23 20:50:05.659053: E tensorflow/stream_executor/cuda/cuda_blas.cc:232] failed to create cublas handle: CUBLAS_STATUS_NOT_INITIALIZED\n",
      "2022-11-23 20:50:05.659094: E tensorflow/stream_executor/cuda/cuda_blas.cc:234] Failure to initialize cublas may be due to OOM (cublas needs some free memory when you initialize it, and your deep-learning framework may have preallocated more than its fair share), or may be because this binary was not built with support for the GPU in your machine.\n",
      "2022-11-23 20:50:05.659277: W tensorflow/core/framework/op_kernel.cc:1745] OP_REQUIRES failed at conv_ops.cc:1120 : NOT_FOUND: No algorithm worked!  Error messages:\n",
      "  Profiling failure on CUDNN engine 1#TC: UNKNOWN: CUDNN_STATUS_EXECUTION_FAILED\n",
      "in tensorflow/stream_executor/cuda/cuda_dnn.cc(4023): 'cudnnConvolutionForward( cudnn.handle(), alpha, input_nd_.handle(), input_data.opaque(), filter_.handle(), filter_data.opaque(), conv_.handle(), ToConvForwardAlgo(algo), scratch_memory.opaque(), scratch_memory.size(), beta, output_nd_.handle(), output_data.opaque())'\n",
      "  Profiling failure on CUDNN engine 1: UNKNOWN: CUDNN_STATUS_EXECUTION_FAILED\n",
      "in tensorflow/stream_executor/cuda/cuda_dnn.cc(4023): 'cudnnConvolutionForward( cudnn.handle(), alpha, input_nd_.handle(), input_data.opaque(), filter_.handle(), filter_data.opaque(), conv_.handle(), ToConvForwardAlgo(algo), scratch_memory.opaque(), scratch_memory.size(), beta, output_nd_.handle(), output_data.opaque())'\n",
      "  Profiling failure on CUDNN engine 0#TC: UNKNOWN: CUDNN_STATUS_EXECUTION_FAILED\n",
      "in tensorflow/stream_executor/cuda/cuda_dnn.cc(4023): 'cudnnConvolutionForward( cudnn.handle(), alpha, input_nd_.handle(), input_data.opaque(), filter_.handle(), filter_data.opaque(), conv_.handle(), ToConvForwardAlgo(algo), scratch_memory.opaque(), scratch_memory.size(), beta, output_nd_.handle(), output_data.opaque())'\n",
      "  Profiling failure on CUDNN engine 0: UNKNOWN: CUDNN_STATUS_EXECUTION_FAILED\n",
      "in tensorflow/stream_executor/cuda/cuda_dnn.cc(4023): 'cudnnConvolutionForward( cudnn.handle(), alpha, input_nd_.handle(), input_data.opaque(), filter_.handle(), filter_data.opaque(), conv_.handle(), ToConvForwardAlgo(algo), scratch_memory.opaque(), scratch_memory.size(), beta, output_nd_.handle(), output_data.opaque())'\n",
      "  Profiling failure on CUDNN engine 2#TC: RESOURCE_EXHAUSTED: Out of memory while trying to allocate 64089856 bytes.\n",
      "  Profiling failure on CUDNN engine 2: RESOURCE_EXHAUSTED: Out of memory while trying to allocate 64089856 bytes.\n",
      "  Profiling failure on CUDNN engine 4#TC: RESOURCE_EXHAUSTED: Out of memory while trying to allocate 354946432 bytes.\n",
      "  Profiling failure on CUDNN engine 4: RESOURCE_EXHAUSTED: Out of memory while trying to allocate 354946432 bytes.\n",
      "  Profiling failure on CUDNN engine 6#TC: UNKNOWN: CUDNN_STATUS_EXECUTION_FAILED\n",
      "in tensorflow/stream_executor/cuda/cuda_dnn.cc(4023): 'cudnnConvolutionForward( cudnn.handle(), alpha, input_nd_.handle(), input_data.opaque(), filter_.handle(), filter_data.opaque(), conv_.handle(), ToConvForwardAlgo(algo), scratch_memory.opaque(), scratch_memory.size(), beta, output_nd_.handle(), output_data.opaque())'\n",
      "  Profiling failure on CUDNN engine 6: UNKNOWN: CUDNN_STATUS_EXECUTION_FAILED\n",
      "in tensorflow/stream_executor/cuda/cuda_dnn.cc(4023): 'cudnnConvolutionForward( cudnn.handle(), alpha, input_nd_.handle(), input_data.opaque(), filter_.handle(), filter_data.opaque(), conv_.handle(), ToConvForwardAlgo(algo), scratch_memory.opaque(), scratch_memory.size(), beta, output_nd_.handle(), output_data.opaque())'\n",
      "  Profiling failure on CUDNN engine 5#TC: UNKNOWN: CUDNN_STATUS_INTERNAL_ERROR\n",
      "in tensorflow/stream_executor/cuda/cuda_dnn.cc(4023): 'cudnnConvolutionForward( cudnn.handle(), alpha, input_nd_.handle(), input_data.opaque(), filter_.handle(), filter_data.opaque(), conv_.handle(), ToConvForwardAlgo(algo), scratch_memory.opaque(), scratch_memory.size(), beta, output_nd_.handle(), output_data.opaque())'\n",
      "  Profiling failure on CUDNN engine 5: UNKNOWN: CUDNN_STATUS_INTERNAL_ERROR\n",
      "in tensorflow/stream_executor/cuda/cuda_dnn.cc(4023): 'cudnnConvolutionForward( cudnn.handle(), alpha, input_nd_.handle(), input_data.opaque(), filter_.handle(), filter_data.opaque(), conv_.handle(), ToConvForwardAlgo(algo), scratch_memory.opaque(), scratch_memory.size(), beta, output_nd_.handle(), output_data.opaque())'\n",
      "  Profiling failure on CUDNN engine 7#TC: RESOURCE_EXHAUSTED: Out of memory while trying to allocate 237583360 bytes.\n",
      "  Profiling failure on CUDNN engine 7: RESOURCE_EXHAUSTED: Out of memory while trying to allocate 237583360 bytes.\n"
     ]
    },
    {
     "ename": "NotFoundError",
     "evalue": "Graph execution error:\n\nDetected at node 'sequential_8/conv2d_8/Conv2D' defined at (most recent call last):\n    File \"/opt/saturncloud/envs/saturn/lib/python3.9/runpy.py\", line 197, in _run_module_as_main\n      return _run_code(code, main_globals, None,\n    File \"/opt/saturncloud/envs/saturn/lib/python3.9/runpy.py\", line 87, in _run_code\n      exec(code, run_globals)\n    File \"/opt/saturncloud/envs/saturn/lib/python3.9/site-packages/ipykernel_launcher.py\", line 17, in <module>\n      app.launch_new_instance()\n    File \"/opt/saturncloud/envs/saturn/lib/python3.9/site-packages/traitlets/config/application.py\", line 978, in launch_instance\n      app.start()\n    File \"/opt/saturncloud/envs/saturn/lib/python3.9/site-packages/ipykernel/kernelapp.py\", line 712, in start\n      self.io_loop.start()\n    File \"/opt/saturncloud/envs/saturn/lib/python3.9/site-packages/tornado/platform/asyncio.py\", line 199, in start\n      self.asyncio_loop.run_forever()\n    File \"/opt/saturncloud/envs/saturn/lib/python3.9/asyncio/base_events.py\", line 601, in run_forever\n      self._run_once()\n    File \"/opt/saturncloud/envs/saturn/lib/python3.9/asyncio/base_events.py\", line 1905, in _run_once\n      handle._run()\n    File \"/opt/saturncloud/envs/saturn/lib/python3.9/asyncio/events.py\", line 80, in _run\n      self._context.run(self._callback, *self._args)\n    File \"/opt/saturncloud/envs/saturn/lib/python3.9/site-packages/ipykernel/kernelbase.py\", line 504, in dispatch_queue\n      await self.process_one()\n    File \"/opt/saturncloud/envs/saturn/lib/python3.9/site-packages/ipykernel/kernelbase.py\", line 493, in process_one\n      await dispatch(*args)\n    File \"/opt/saturncloud/envs/saturn/lib/python3.9/site-packages/ipykernel/kernelbase.py\", line 400, in dispatch_shell\n      await result\n    File \"/opt/saturncloud/envs/saturn/lib/python3.9/site-packages/ipykernel/kernelbase.py\", line 724, in execute_request\n      reply_content = await reply_content\n    File \"/opt/saturncloud/envs/saturn/lib/python3.9/site-packages/ipykernel/ipkernel.py\", line 383, in do_execute\n      res = shell.run_cell(\n    File \"/opt/saturncloud/envs/saturn/lib/python3.9/site-packages/ipykernel/zmqshell.py\", line 528, in run_cell\n      return super().run_cell(*args, **kwargs)\n    File \"/opt/saturncloud/envs/saturn/lib/python3.9/site-packages/IPython/core/interactiveshell.py\", line 2885, in run_cell\n      result = self._run_cell(\n    File \"/opt/saturncloud/envs/saturn/lib/python3.9/site-packages/IPython/core/interactiveshell.py\", line 2940, in _run_cell\n      return runner(coro)\n    File \"/opt/saturncloud/envs/saturn/lib/python3.9/site-packages/IPython/core/async_helpers.py\", line 129, in _pseudo_sync_runner\n      coro.send(None)\n    File \"/opt/saturncloud/envs/saturn/lib/python3.9/site-packages/IPython/core/interactiveshell.py\", line 3139, in run_cell_async\n      has_raised = await self.run_ast_nodes(code_ast.body, cell_name,\n    File \"/opt/saturncloud/envs/saturn/lib/python3.9/site-packages/IPython/core/interactiveshell.py\", line 3318, in run_ast_nodes\n      if await self.run_code(code, result, async_=asy):\n    File \"/opt/saturncloud/envs/saturn/lib/python3.9/site-packages/IPython/core/interactiveshell.py\", line 3378, in run_code\n      exec(code_obj, self.user_global_ns, self.user_ns)\n    File \"/tmp/ipykernel_2594/2461656346.py\", line 1, in <module>\n      model.fit(\n    File \"/opt/saturncloud/envs/saturn/lib/python3.9/site-packages/keras/utils/traceback_utils.py\", line 64, in error_handler\n      return fn(*args, **kwargs)\n    File \"/opt/saturncloud/envs/saturn/lib/python3.9/site-packages/keras/engine/training.py\", line 1409, in fit\n      tmp_logs = self.train_function(iterator)\n    File \"/opt/saturncloud/envs/saturn/lib/python3.9/site-packages/keras/engine/training.py\", line 1051, in train_function\n      return step_function(self, iterator)\n    File \"/opt/saturncloud/envs/saturn/lib/python3.9/site-packages/keras/engine/training.py\", line 1040, in step_function\n      outputs = model.distribute_strategy.run(run_step, args=(data,))\n    File \"/opt/saturncloud/envs/saturn/lib/python3.9/site-packages/keras/engine/training.py\", line 1030, in run_step\n      outputs = model.train_step(data)\n    File \"/opt/saturncloud/envs/saturn/lib/python3.9/site-packages/keras/engine/training.py\", line 889, in train_step\n      y_pred = self(x, training=True)\n    File \"/opt/saturncloud/envs/saturn/lib/python3.9/site-packages/keras/utils/traceback_utils.py\", line 64, in error_handler\n      return fn(*args, **kwargs)\n    File \"/opt/saturncloud/envs/saturn/lib/python3.9/site-packages/keras/engine/training.py\", line 490, in __call__\n      return super().__call__(*args, **kwargs)\n    File \"/opt/saturncloud/envs/saturn/lib/python3.9/site-packages/keras/utils/traceback_utils.py\", line 64, in error_handler\n      return fn(*args, **kwargs)\n    File \"/opt/saturncloud/envs/saturn/lib/python3.9/site-packages/keras/engine/base_layer.py\", line 1014, in __call__\n      outputs = call_fn(inputs, *args, **kwargs)\n    File \"/opt/saturncloud/envs/saturn/lib/python3.9/site-packages/keras/utils/traceback_utils.py\", line 92, in error_handler\n      return fn(*args, **kwargs)\n    File \"/opt/saturncloud/envs/saturn/lib/python3.9/site-packages/keras/engine/sequential.py\", line 374, in call\n      return super(Sequential, self).call(inputs, training=training, mask=mask)\n    File \"/opt/saturncloud/envs/saturn/lib/python3.9/site-packages/keras/engine/functional.py\", line 458, in call\n      return self._run_internal_graph(\n    File \"/opt/saturncloud/envs/saturn/lib/python3.9/site-packages/keras/engine/functional.py\", line 596, in _run_internal_graph\n      outputs = node.layer(*args, **kwargs)\n    File \"/opt/saturncloud/envs/saturn/lib/python3.9/site-packages/keras/utils/traceback_utils.py\", line 64, in error_handler\n      return fn(*args, **kwargs)\n    File \"/opt/saturncloud/envs/saturn/lib/python3.9/site-packages/keras/engine/base_layer.py\", line 1014, in __call__\n      outputs = call_fn(inputs, *args, **kwargs)\n    File \"/opt/saturncloud/envs/saturn/lib/python3.9/site-packages/keras/utils/traceback_utils.py\", line 92, in error_handler\n      return fn(*args, **kwargs)\n    File \"/opt/saturncloud/envs/saturn/lib/python3.9/site-packages/keras/layers/convolutional/base_conv.py\", line 250, in call\n      outputs = self.convolution_op(inputs, self.kernel)\n    File \"/opt/saturncloud/envs/saturn/lib/python3.9/site-packages/keras/layers/convolutional/base_conv.py\", line 225, in convolution_op\n      return tf.nn.convolution(\nNode: 'sequential_8/conv2d_8/Conv2D'\nNo algorithm worked!  Error messages:\n  Profiling failure on CUDNN engine 1#TC: UNKNOWN: CUDNN_STATUS_EXECUTION_FAILED\nin tensorflow/stream_executor/cuda/cuda_dnn.cc(4023): 'cudnnConvolutionForward( cudnn.handle(), alpha, input_nd_.handle(), input_data.opaque(), filter_.handle(), filter_data.opaque(), conv_.handle(), ToConvForwardAlgo(algo), scratch_memory.opaque(), scratch_memory.size(), beta, output_nd_.handle(), output_data.opaque())'\n  Profiling failure on CUDNN engine 1: UNKNOWN: CUDNN_STATUS_EXECUTION_FAILED\nin tensorflow/stream_executor/cuda/cuda_dnn.cc(4023): 'cudnnConvolutionForward( cudnn.handle(), alpha, input_nd_.handle(), input_data.opaque(), filter_.handle(), filter_data.opaque(), conv_.handle(), ToConvForwardAlgo(algo), scratch_memory.opaque(), scratch_memory.size(), beta, output_nd_.handle(), output_data.opaque())'\n  Profiling failure on CUDNN engine 0#TC: UNKNOWN: CUDNN_STATUS_EXECUTION_FAILED\nin tensorflow/stream_executor/cuda/cuda_dnn.cc(4023): 'cudnnConvolutionForward( cudnn.handle(), alpha, input_nd_.handle(), input_data.opaque(), filter_.handle(), filter_data.opaque(), conv_.handle(), ToConvForwardAlgo(algo), scratch_memory.opaque(), scratch_memory.size(), beta, output_nd_.handle(), output_data.opaque())'\n  Profiling failure on CUDNN engine 0: UNKNOWN: CUDNN_STATUS_EXECUTION_FAILED\nin tensorflow/stream_executor/cuda/cuda_dnn.cc(4023): 'cudnnConvolutionForward( cudnn.handle(), alpha, input_nd_.handle(), input_data.opaque(), filter_.handle(), filter_data.opaque(), conv_.handle(), ToConvForwardAlgo(algo), scratch_memory.opaque(), scratch_memory.size(), beta, output_nd_.handle(), output_data.opaque())'\n  Profiling failure on CUDNN engine 2#TC: RESOURCE_EXHAUSTED: Out of memory while trying to allocate 64089856 bytes.\n  Profiling failure on CUDNN engine 2: RESOURCE_EXHAUSTED: Out of memory while trying to allocate 64089856 bytes.\n  Profiling failure on CUDNN engine 4#TC: RESOURCE_EXHAUSTED: Out of memory while trying to allocate 354946432 bytes.\n  Profiling failure on CUDNN engine 4: RESOURCE_EXHAUSTED: Out of memory while trying to allocate 354946432 bytes.\n  Profiling failure on CUDNN engine 6#TC: UNKNOWN: CUDNN_STATUS_EXECUTION_FAILED\nin tensorflow/stream_executor/cuda/cuda_dnn.cc(4023): 'cudnnConvolutionForward( cudnn.handle(), alpha, input_nd_.handle(), input_data.opaque(), filter_.handle(), filter_data.opaque(), conv_.handle(), ToConvForwardAlgo(algo), scratch_memory.opaque(), scratch_memory.size(), beta, output_nd_.handle(), output_data.opaque())'\n  Profiling failure on CUDNN engine 6: UNKNOWN: CUDNN_STATUS_EXECUTION_FAILED\nin tensorflow/stream_executor/cuda/cuda_dnn.cc(4023): 'cudnnConvolutionForward( cudnn.handle(), alpha, input_nd_.handle(), input_data.opaque(), filter_.handle(), filter_data.opaque(), conv_.handle(), ToConvForwardAlgo(algo), scratch_memory.opaque(), scratch_memory.size(), beta, output_nd_.handle(), output_data.opaque())'\n  Profiling failure on CUDNN engine 5#TC: UNKNOWN: CUDNN_STATUS_INTERNAL_ERROR\nin tensorflow/stream_executor/cuda/cuda_dnn.cc(4023): 'cudnnConvolutionForward( cudnn.handle(), alpha, input_nd_.handle(), input_data.opaque(), filter_.handle(), filter_data.opaque(), conv_.handle(), ToConvForwardAlgo(algo), scratch_memory.opaque(), scratch_memory.size(), beta, output_nd_.handle(), output_data.opaque())'\n  Profiling failure on CUDNN engine 5: UNKNOWN: CUDNN_STATUS_INTERNAL_ERROR\nin tensorflow/stream_executor/cuda/cuda_dnn.cc(4023): 'cudnnConvolutionForward( cudnn.handle(), alpha, input_nd_.handle(), input_data.opaque(), filter_.handle(), filter_data.opaque(), conv_.handle(), ToConvForwardAlgo(algo), scratch_memory.opaque(), scratch_memory.size(), beta, output_nd_.handle(), output_data.opaque())'\n  Profiling failure on CUDNN engine 7#TC: RESOURCE_EXHAUSTED: Out of memory while trying to allocate 237583360 bytes.\n  Profiling failure on CUDNN engine 7: RESOURCE_EXHAUSTED: Out of memory while trying to allocate 237583360 bytes.\n\t [[{{node sequential_8/conv2d_8/Conv2D}}]] [Op:__inference_train_function_3824]",
     "output_type": "error",
     "traceback": [
      "\u001b[0;31m---------------------------------------------------------------------------\u001b[0m",
      "\u001b[0;31mNotFoundError\u001b[0m                             Traceback (most recent call last)",
      "Cell \u001b[0;32mIn [64], line 1\u001b[0m\n\u001b[0;32m----> 1\u001b[0m model\u001b[38;5;241m.\u001b[39mfit(\n\u001b[1;32m      2\u001b[0m     train_ds,\n\u001b[1;32m      3\u001b[0m     epochs\u001b[38;5;241m=\u001b[39m\u001b[38;5;241m10\u001b[39m,\n\u001b[1;32m      4\u001b[0m     validation_data\u001b[38;5;241m=\u001b[39mtest_ds\n\u001b[1;32m      5\u001b[0m )\n",
      "File \u001b[0;32m/opt/saturncloud/envs/saturn/lib/python3.9/site-packages/keras/utils/traceback_utils.py:67\u001b[0m, in \u001b[0;36mfilter_traceback.<locals>.error_handler\u001b[0;34m(*args, **kwargs)\u001b[0m\n\u001b[1;32m     65\u001b[0m \u001b[38;5;28;01mexcept\u001b[39;00m \u001b[38;5;167;01mException\u001b[39;00m \u001b[38;5;28;01mas\u001b[39;00m e:  \u001b[38;5;66;03m# pylint: disable=broad-except\u001b[39;00m\n\u001b[1;32m     66\u001b[0m   filtered_tb \u001b[38;5;241m=\u001b[39m _process_traceback_frames(e\u001b[38;5;241m.\u001b[39m__traceback__)\n\u001b[0;32m---> 67\u001b[0m   \u001b[38;5;28;01mraise\u001b[39;00m e\u001b[38;5;241m.\u001b[39mwith_traceback(filtered_tb) \u001b[38;5;28;01mfrom\u001b[39;00m \u001b[38;5;28mNone\u001b[39m\n\u001b[1;32m     68\u001b[0m \u001b[38;5;28;01mfinally\u001b[39;00m:\n\u001b[1;32m     69\u001b[0m   \u001b[38;5;28;01mdel\u001b[39;00m filtered_tb\n",
      "File \u001b[0;32m/opt/saturncloud/envs/saturn/lib/python3.9/site-packages/tensorflow/python/eager/execute.py:54\u001b[0m, in \u001b[0;36mquick_execute\u001b[0;34m(op_name, num_outputs, inputs, attrs, ctx, name)\u001b[0m\n\u001b[1;32m     52\u001b[0m \u001b[38;5;28;01mtry\u001b[39;00m:\n\u001b[1;32m     53\u001b[0m   ctx\u001b[38;5;241m.\u001b[39mensure_initialized()\n\u001b[0;32m---> 54\u001b[0m   tensors \u001b[38;5;241m=\u001b[39m pywrap_tfe\u001b[38;5;241m.\u001b[39mTFE_Py_Execute(ctx\u001b[38;5;241m.\u001b[39m_handle, device_name, op_name,\n\u001b[1;32m     55\u001b[0m                                       inputs, attrs, num_outputs)\n\u001b[1;32m     56\u001b[0m \u001b[38;5;28;01mexcept\u001b[39;00m core\u001b[38;5;241m.\u001b[39m_NotOkStatusException \u001b[38;5;28;01mas\u001b[39;00m e:\n\u001b[1;32m     57\u001b[0m   \u001b[38;5;28;01mif\u001b[39;00m name \u001b[38;5;129;01mis\u001b[39;00m \u001b[38;5;129;01mnot\u001b[39;00m \u001b[38;5;28;01mNone\u001b[39;00m:\n",
      "\u001b[0;31mNotFoundError\u001b[0m: Graph execution error:\n\nDetected at node 'sequential_8/conv2d_8/Conv2D' defined at (most recent call last):\n    File \"/opt/saturncloud/envs/saturn/lib/python3.9/runpy.py\", line 197, in _run_module_as_main\n      return _run_code(code, main_globals, None,\n    File \"/opt/saturncloud/envs/saturn/lib/python3.9/runpy.py\", line 87, in _run_code\n      exec(code, run_globals)\n    File \"/opt/saturncloud/envs/saturn/lib/python3.9/site-packages/ipykernel_launcher.py\", line 17, in <module>\n      app.launch_new_instance()\n    File \"/opt/saturncloud/envs/saturn/lib/python3.9/site-packages/traitlets/config/application.py\", line 978, in launch_instance\n      app.start()\n    File \"/opt/saturncloud/envs/saturn/lib/python3.9/site-packages/ipykernel/kernelapp.py\", line 712, in start\n      self.io_loop.start()\n    File \"/opt/saturncloud/envs/saturn/lib/python3.9/site-packages/tornado/platform/asyncio.py\", line 199, in start\n      self.asyncio_loop.run_forever()\n    File \"/opt/saturncloud/envs/saturn/lib/python3.9/asyncio/base_events.py\", line 601, in run_forever\n      self._run_once()\n    File \"/opt/saturncloud/envs/saturn/lib/python3.9/asyncio/base_events.py\", line 1905, in _run_once\n      handle._run()\n    File \"/opt/saturncloud/envs/saturn/lib/python3.9/asyncio/events.py\", line 80, in _run\n      self._context.run(self._callback, *self._args)\n    File \"/opt/saturncloud/envs/saturn/lib/python3.9/site-packages/ipykernel/kernelbase.py\", line 504, in dispatch_queue\n      await self.process_one()\n    File \"/opt/saturncloud/envs/saturn/lib/python3.9/site-packages/ipykernel/kernelbase.py\", line 493, in process_one\n      await dispatch(*args)\n    File \"/opt/saturncloud/envs/saturn/lib/python3.9/site-packages/ipykernel/kernelbase.py\", line 400, in dispatch_shell\n      await result\n    File \"/opt/saturncloud/envs/saturn/lib/python3.9/site-packages/ipykernel/kernelbase.py\", line 724, in execute_request\n      reply_content = await reply_content\n    File \"/opt/saturncloud/envs/saturn/lib/python3.9/site-packages/ipykernel/ipkernel.py\", line 383, in do_execute\n      res = shell.run_cell(\n    File \"/opt/saturncloud/envs/saturn/lib/python3.9/site-packages/ipykernel/zmqshell.py\", line 528, in run_cell\n      return super().run_cell(*args, **kwargs)\n    File \"/opt/saturncloud/envs/saturn/lib/python3.9/site-packages/IPython/core/interactiveshell.py\", line 2885, in run_cell\n      result = self._run_cell(\n    File \"/opt/saturncloud/envs/saturn/lib/python3.9/site-packages/IPython/core/interactiveshell.py\", line 2940, in _run_cell\n      return runner(coro)\n    File \"/opt/saturncloud/envs/saturn/lib/python3.9/site-packages/IPython/core/async_helpers.py\", line 129, in _pseudo_sync_runner\n      coro.send(None)\n    File \"/opt/saturncloud/envs/saturn/lib/python3.9/site-packages/IPython/core/interactiveshell.py\", line 3139, in run_cell_async\n      has_raised = await self.run_ast_nodes(code_ast.body, cell_name,\n    File \"/opt/saturncloud/envs/saturn/lib/python3.9/site-packages/IPython/core/interactiveshell.py\", line 3318, in run_ast_nodes\n      if await self.run_code(code, result, async_=asy):\n    File \"/opt/saturncloud/envs/saturn/lib/python3.9/site-packages/IPython/core/interactiveshell.py\", line 3378, in run_code\n      exec(code_obj, self.user_global_ns, self.user_ns)\n    File \"/tmp/ipykernel_2594/2461656346.py\", line 1, in <module>\n      model.fit(\n    File \"/opt/saturncloud/envs/saturn/lib/python3.9/site-packages/keras/utils/traceback_utils.py\", line 64, in error_handler\n      return fn(*args, **kwargs)\n    File \"/opt/saturncloud/envs/saturn/lib/python3.9/site-packages/keras/engine/training.py\", line 1409, in fit\n      tmp_logs = self.train_function(iterator)\n    File \"/opt/saturncloud/envs/saturn/lib/python3.9/site-packages/keras/engine/training.py\", line 1051, in train_function\n      return step_function(self, iterator)\n    File \"/opt/saturncloud/envs/saturn/lib/python3.9/site-packages/keras/engine/training.py\", line 1040, in step_function\n      outputs = model.distribute_strategy.run(run_step, args=(data,))\n    File \"/opt/saturncloud/envs/saturn/lib/python3.9/site-packages/keras/engine/training.py\", line 1030, in run_step\n      outputs = model.train_step(data)\n    File \"/opt/saturncloud/envs/saturn/lib/python3.9/site-packages/keras/engine/training.py\", line 889, in train_step\n      y_pred = self(x, training=True)\n    File \"/opt/saturncloud/envs/saturn/lib/python3.9/site-packages/keras/utils/traceback_utils.py\", line 64, in error_handler\n      return fn(*args, **kwargs)\n    File \"/opt/saturncloud/envs/saturn/lib/python3.9/site-packages/keras/engine/training.py\", line 490, in __call__\n      return super().__call__(*args, **kwargs)\n    File \"/opt/saturncloud/envs/saturn/lib/python3.9/site-packages/keras/utils/traceback_utils.py\", line 64, in error_handler\n      return fn(*args, **kwargs)\n    File \"/opt/saturncloud/envs/saturn/lib/python3.9/site-packages/keras/engine/base_layer.py\", line 1014, in __call__\n      outputs = call_fn(inputs, *args, **kwargs)\n    File \"/opt/saturncloud/envs/saturn/lib/python3.9/site-packages/keras/utils/traceback_utils.py\", line 92, in error_handler\n      return fn(*args, **kwargs)\n    File \"/opt/saturncloud/envs/saturn/lib/python3.9/site-packages/keras/engine/sequential.py\", line 374, in call\n      return super(Sequential, self).call(inputs, training=training, mask=mask)\n    File \"/opt/saturncloud/envs/saturn/lib/python3.9/site-packages/keras/engine/functional.py\", line 458, in call\n      return self._run_internal_graph(\n    File \"/opt/saturncloud/envs/saturn/lib/python3.9/site-packages/keras/engine/functional.py\", line 596, in _run_internal_graph\n      outputs = node.layer(*args, **kwargs)\n    File \"/opt/saturncloud/envs/saturn/lib/python3.9/site-packages/keras/utils/traceback_utils.py\", line 64, in error_handler\n      return fn(*args, **kwargs)\n    File \"/opt/saturncloud/envs/saturn/lib/python3.9/site-packages/keras/engine/base_layer.py\", line 1014, in __call__\n      outputs = call_fn(inputs, *args, **kwargs)\n    File \"/opt/saturncloud/envs/saturn/lib/python3.9/site-packages/keras/utils/traceback_utils.py\", line 92, in error_handler\n      return fn(*args, **kwargs)\n    File \"/opt/saturncloud/envs/saturn/lib/python3.9/site-packages/keras/layers/convolutional/base_conv.py\", line 250, in call\n      outputs = self.convolution_op(inputs, self.kernel)\n    File \"/opt/saturncloud/envs/saturn/lib/python3.9/site-packages/keras/layers/convolutional/base_conv.py\", line 225, in convolution_op\n      return tf.nn.convolution(\nNode: 'sequential_8/conv2d_8/Conv2D'\nNo algorithm worked!  Error messages:\n  Profiling failure on CUDNN engine 1#TC: UNKNOWN: CUDNN_STATUS_EXECUTION_FAILED\nin tensorflow/stream_executor/cuda/cuda_dnn.cc(4023): 'cudnnConvolutionForward( cudnn.handle(), alpha, input_nd_.handle(), input_data.opaque(), filter_.handle(), filter_data.opaque(), conv_.handle(), ToConvForwardAlgo(algo), scratch_memory.opaque(), scratch_memory.size(), beta, output_nd_.handle(), output_data.opaque())'\n  Profiling failure on CUDNN engine 1: UNKNOWN: CUDNN_STATUS_EXECUTION_FAILED\nin tensorflow/stream_executor/cuda/cuda_dnn.cc(4023): 'cudnnConvolutionForward( cudnn.handle(), alpha, input_nd_.handle(), input_data.opaque(), filter_.handle(), filter_data.opaque(), conv_.handle(), ToConvForwardAlgo(algo), scratch_memory.opaque(), scratch_memory.size(), beta, output_nd_.handle(), output_data.opaque())'\n  Profiling failure on CUDNN engine 0#TC: UNKNOWN: CUDNN_STATUS_EXECUTION_FAILED\nin tensorflow/stream_executor/cuda/cuda_dnn.cc(4023): 'cudnnConvolutionForward( cudnn.handle(), alpha, input_nd_.handle(), input_data.opaque(), filter_.handle(), filter_data.opaque(), conv_.handle(), ToConvForwardAlgo(algo), scratch_memory.opaque(), scratch_memory.size(), beta, output_nd_.handle(), output_data.opaque())'\n  Profiling failure on CUDNN engine 0: UNKNOWN: CUDNN_STATUS_EXECUTION_FAILED\nin tensorflow/stream_executor/cuda/cuda_dnn.cc(4023): 'cudnnConvolutionForward( cudnn.handle(), alpha, input_nd_.handle(), input_data.opaque(), filter_.handle(), filter_data.opaque(), conv_.handle(), ToConvForwardAlgo(algo), scratch_memory.opaque(), scratch_memory.size(), beta, output_nd_.handle(), output_data.opaque())'\n  Profiling failure on CUDNN engine 2#TC: RESOURCE_EXHAUSTED: Out of memory while trying to allocate 64089856 bytes.\n  Profiling failure on CUDNN engine 2: RESOURCE_EXHAUSTED: Out of memory while trying to allocate 64089856 bytes.\n  Profiling failure on CUDNN engine 4#TC: RESOURCE_EXHAUSTED: Out of memory while trying to allocate 354946432 bytes.\n  Profiling failure on CUDNN engine 4: RESOURCE_EXHAUSTED: Out of memory while trying to allocate 354946432 bytes.\n  Profiling failure on CUDNN engine 6#TC: UNKNOWN: CUDNN_STATUS_EXECUTION_FAILED\nin tensorflow/stream_executor/cuda/cuda_dnn.cc(4023): 'cudnnConvolutionForward( cudnn.handle(), alpha, input_nd_.handle(), input_data.opaque(), filter_.handle(), filter_data.opaque(), conv_.handle(), ToConvForwardAlgo(algo), scratch_memory.opaque(), scratch_memory.size(), beta, output_nd_.handle(), output_data.opaque())'\n  Profiling failure on CUDNN engine 6: UNKNOWN: CUDNN_STATUS_EXECUTION_FAILED\nin tensorflow/stream_executor/cuda/cuda_dnn.cc(4023): 'cudnnConvolutionForward( cudnn.handle(), alpha, input_nd_.handle(), input_data.opaque(), filter_.handle(), filter_data.opaque(), conv_.handle(), ToConvForwardAlgo(algo), scratch_memory.opaque(), scratch_memory.size(), beta, output_nd_.handle(), output_data.opaque())'\n  Profiling failure on CUDNN engine 5#TC: UNKNOWN: CUDNN_STATUS_INTERNAL_ERROR\nin tensorflow/stream_executor/cuda/cuda_dnn.cc(4023): 'cudnnConvolutionForward( cudnn.handle(), alpha, input_nd_.handle(), input_data.opaque(), filter_.handle(), filter_data.opaque(), conv_.handle(), ToConvForwardAlgo(algo), scratch_memory.opaque(), scratch_memory.size(), beta, output_nd_.handle(), output_data.opaque())'\n  Profiling failure on CUDNN engine 5: UNKNOWN: CUDNN_STATUS_INTERNAL_ERROR\nin tensorflow/stream_executor/cuda/cuda_dnn.cc(4023): 'cudnnConvolutionForward( cudnn.handle(), alpha, input_nd_.handle(), input_data.opaque(), filter_.handle(), filter_data.opaque(), conv_.handle(), ToConvForwardAlgo(algo), scratch_memory.opaque(), scratch_memory.size(), beta, output_nd_.handle(), output_data.opaque())'\n  Profiling failure on CUDNN engine 7#TC: RESOURCE_EXHAUSTED: Out of memory while trying to allocate 237583360 bytes.\n  Profiling failure on CUDNN engine 7: RESOURCE_EXHAUSTED: Out of memory while trying to allocate 237583360 bytes.\n\t [[{{node sequential_8/conv2d_8/Conv2D}}]] [Op:__inference_train_function_3824]"
     ]
    }
   ],
   "source": [
    "model.fit(\n",
    "    train_ds,\n",
    "    epochs=10,\n",
    "    validation_data=test_ds\n",
    ")"
   ]
  },
  {
   "cell_type": "code",
   "execution_count": null,
   "id": "43c7ba5c",
   "metadata": {},
   "outputs": [],
   "source": []
  },
  {
   "cell_type": "code",
   "execution_count": null,
   "id": "5e90d1d6",
   "metadata": {},
   "outputs": [],
   "source": []
  }
 ],
 "metadata": {
  "kernelspec": {
   "display_name": "saturn (Python 3)",
   "language": "python",
   "name": "python3"
  },
  "language_info": {
   "codemirror_mode": {
    "name": "ipython",
    "version": 3
   },
   "file_extension": ".py",
   "mimetype": "text/x-python",
   "name": "python",
   "nbconvert_exporter": "python",
   "pygments_lexer": "ipython3",
   "version": "3.9.13"
  }
 },
 "nbformat": 4,
 "nbformat_minor": 5
}
